Workbook

Sheet Samples
A1: batchID | B1: Exp_Type | C1: buffer_position | D1: Vial | E1: Sample Name | F1: Volume | G1: Slot | H1: Buffer | I1: Acq. method | J1: Sample Type | K1: Run Time | L1: Flow Rate | M1: Column type | N1: Proc. method | O1: Injection source | P1: Data file | Q1: Inj/Vial | R1: Valve Position
A2: a3 | B2: X-ray_only | C2: 1 | D2: D1F-C03 | E2: BSA_30mg_20ul | F2: 20 | G2: col_pos1 | H2: PBS | I2: test.amx | J2: Sample | K2: =VLOOKUP($I2,Info!$C$11:$H$32,4,0) -> 4 | L2: =VLOOKUP($I2,Info!$C$11:$H$32,5,0) -> 0.3 | M2: =VLOOKUP($I2,Info!$C$11:$H$32,3,0) -> no_column | N2: =VLOOKUP($I2,Info!$C$11:$H$32,6,0) -> CSV_ADF_export.pmx | O2: =VLOOKUP($I2,Info!$C$11:$J$32,7,0) -> HipAls | P2: a | Q2: =VLOOKUP($I2,Info!$C$11:$K$32,9,0) -> 1 | R2: =VLOOKUP($I2,Info!$C$11:$L$33, 10,0) -> A
A3: a4 | B3: X-ray_only | C3: 1 | D3: D1F-C03 | E3: BSA_30mg_20ul_B | F3: 20 | G3: col_pos1 | H3: PBS | I3: test.amx | J3: Sample | K3: =VLOOKUP($I3,Info!$C$11:$H$32,4,0) -> 4 | L3: =VLOOKUP($I3,Info!$C$11:$H$32,5,0) -> 0.3 | M3: =VLOOKUP($I3,Info!$C$11:$H$32,3,0) -> no_column | N3: =VLOOKUP($I3,Info!$C$11:$H$32,6,0) -> CSV_ADF_export.pmx | O3: =VLOOKUP($I3,Info!$C$11:$J$32,7,0) -> HipAls | P3: a | Q3: =VLOOKUP($I3,Info!$C$11:$K$32,9,0) -> 1 | R3: =VLOOKUP($I3,Info!$C$11:$L$33, 10,0) -> A
A4: a5 | B4: X-ray_only | C4: 1 | D4: D1F-C03 | E4: BSA_30mg_50ul | F4: 50 | G4: col_pos2 | H4: Water | I4: test.amx | J4: Sample | K4: =VLOOKUP($I4,Info!$C$11:$H$32,4,0) -> 4 | L4: =VLOOKUP($I4,Info!$C$11:$H$32,5,0) -> 0.3 | M4: =VLOOKUP($I4,Info!$C$11:$H$32,3,0) -> no_column | N4: =VLOOKUP($I4,Info!$C$11:$H$32,6,0) -> CSV_ADF_export.pmx | O4: =VLOOKUP($I4,Info!$C$11:$J$32,7,0) -> HipAls | P4: a | Q4: =VLOOKUP($I4,Info!$C$11:$K$32,9,0) -> 1 | R4: =VLOOKUP($I4,Info!$C$11:$L$33, 10,0) -> A
A5: a6 | B5: X-ray_only | C5: 1 | D5: D1F-C03 | E5: BSA_30mg_50ul_test_result | F5: 1 | G5: col_pos1 | H5: Water | I5: test.amx | J5: Sample | K5: =VLOOKUP($I5,Info!$C$11:$H$32,4,0) -> 4 | L5: =VLOOKUP($I5,Info!$C$11:$H$32,5,0) -> 0.3 | M5: =VLOOKUP($I5,Info!$C$11:$H$32,3,0) -> no_column | N5: =VLOOKUP($I5,Info!$C$11:$H$32,6,0) -> CSV_ADF_export.pmx | O5: =VLOOKUP($I5,Info!$C$11:$J$32,7,0) -> HipAls | P5: a | Q5: =VLOOKUP($I5,Info!$C$11:$K$32,9,0) -> 1 | R5: =VLOOKUP($I5,Info!$C$11:$L$33, 10,0) -> A
A6: a6 | B6: X-ray_Regen | C6: 1 | D6: D1F-C03 | E6: BSA_30mg_50ul_test_result | F6: 1 | G6: col_pos2 | H6: Water | I6: test.amx | J6: Sample | K6: =VLOOKUP($I6,Info!$C$11:$H$32,4,0) -> 4 | L6: =VLOOKUP($I6,Info!$C$11:$H$32,5,0) -> 0.3 | M6: =VLOOKUP($I6,Info!$C$11:$H$32,3,0) -> no_column | N6: =VLOOKUP($I6,Info!$C$11:$H$32,6,0) -> CSV_ADF_export.pmx | O6: =VLOOKUP($I6,Info!$C$11:$J$32,7,0) -> HipAls | P6: a | Q6: =VLOOKUP($I6,Info!$C$11:$K$32,9,0) -> 1 | R6: =VLOOKUP($I6,Info!$C$11:$L$33, 10,0) -> A
A7: a7 | B7: X-ray_UV | C7: 2 | D7: D1F-A04 | E7: BSA_6mg_sept_18 | F7: 50 | G7: col_pos2 | H7: Hepes pH8 150mM Nacl 5%glycerol 1mM TCEP | I7: superose6_5_150_channel_A.amx | J7: Sample | K7: =VLOOKUP($I7,Info!$C$11:$H$32,4,0) -> 15 | L7: =VLOOKUP($I7,Info!$C$11:$H$32,5,0) -> 0.3 | M7: =VLOOKUP($I7,Info!$C$11:$H$32,3,0) -> Superose6_5_150 | N7: =VLOOKUP($I7,Info!$C$11:$H$32,6,0) -> CSV_ADF_export.pmx | O7: =VLOOKUP($I7,Info!$C$11:$J$32,7,0) -> HipAls | P7: a | Q7: =VLOOKUP($I7,Info!$C$11:$K$32,9,0) -> 1 | R7: =VLOOKUP($I7,Info!$C$11:$L$33, 10,0) -> A

Sheet Info
A1: Instructions:
A2: 1. Do not change the header line in the Samples sheet.
A3: 2. Do not change this sheet other than the method listing below.
A4: 2. List only valid method files (starting on row 10), and fill in the correct parameters for the method.
A7: valid Vial Names | B7: DF1-***
B8: 1
A10: valid methods | B10: # | C10: Acq. method | D10: ColumnID | E10: Column Type | F10: Run Time | G10: Flow Rate A | H10: Proc. method | I10: Injection source | J10: Data file | K10: Inj/Vial | L10: Valve Position
A11: should be column_type, flowrate, time(min) | B11: 1 | C11: Injection_5.amx | D11: 1 | E11: GE Superdex Increase 200 5/150 GL | F11: 12 | G11: 0.5 | H11: processing_test_AIA.pmx | I11: HipAls | J11: a | K11: 1 | L11: A
B12: 2 | C12: superdex_200_5_150_old.amx | D12: 1 | E12: GE Superdex Increase 200 5/150 GL | F12: 12 | G12: 0.35 | H12: CSV_ADF_export.pmx | I12: HipAls | J12: a | K12: 1 | L12: A
B13: 3 | C13: dSEC2B.amx | D13: 1 | E13: dSEC2 | F13: 15 | G13: 0.35 | H13: CSV_ADF_export.pmx | I13: HipAls | J13: a | K13: 1 | L13: B
B14: 4 | C14: superdex_5_150_channel_B.amx | D14: 1 | E14: GE Superdex Increase 200 5/150 GL | F14: 15 | G14: 0.3 | H14: CSV_ADF_export.pmx | I14: HipAls | J14: a | K14: 1 | L14: B
B15: 5 | C15: noUV_lamp.amx | D15: 1 | E15: None | F15: 5 | G15: 0.35 | H15: CSV_ADF_export.pmx | I15: HipAls | J15: a | K15: 1 | L15: check
B16: 6 | C16: superdex_5_150.amx | D16: 1 | E16: GE Superdex Increase 200 5/150 GL | F16: 20 | G16: 0.35 | H16: CSV_ADF_export.pmx | I16: HipAls | J16: a | K16: 1 | L16: A
B17: 7 | C17: dSEC2_035_25min.amx | D17: 1 | E17: dSEC2 | F17: 15 | G17: 0.35 | H17: CSV_ADF_export.pmx | I17: HipAls | J17: a | K17: 1 | L17: B
B18: 8 | C18: Sepharose4B.amx | D18: 1 | E18: Sepharose4B | F18: 40 | G18: 0.1 | H18: CSV_ADF_export.pmx | I18: HipAls | J18: a | K18: 1 | L18: check
B19: 9 | C19: test.amx | D19: 1 | E19: no_column | F19: 4 | G19: 0.3 | H19: CSV_ADF_export.pmx | I19: HipAls | J19: a | K19: 1 | L19: A
B20: 10 | C20: superdex_10_300_channel_C.amx | D20: 1 | E20: GE Superdex Increase 200 10/300 GL | F20: 40 | G20: 0.75 | H20: CSV_ADF_export.pmx | I20: HipAls | J20: a | K20: 1 | L20: A
B21: 11 | C21: superdex_200_3.2_300.amx | D21: 1 | E21: Superdex 200 Increase 3.2 300 | F21: 40 | G21: 0.075 | H21: CSV_ADF_export.pmx | I21: HipAls | J21: a | K21: 1 | L21: B
B22: 12 | C22: superdex_5_150_channel_C.amx | D22: 1 | E22: GE Superdex Increase 200 5/150 GL | F22: 12 | G22: 0.35 | H22: CSV_ADF_export.pmx | I22: HipAls | J22: a | K22: 1 | L22: A
B23: 13 | C23: superdex_10_300_channel_B.amx | D23: 1 | E23: GE Superdex Increase 200 10/300 GL | F23: 50 | G23: 0.5 | H23: CSV_ADF_export.pmx | I23: HipAls | J23: a | K23: 1 | L23: B
... B29: 19 | C29: superdex75_5_150_channel_A.amx | D29: 1 | E29: GE Superdex Increase 75 5/150 GL | F29: 15 | G29: 0.3 | H29: CSV_ADF_export.pmx | I29: HipAls | J29: a | K29: 1 | L29: A
A30: valid column type | C30: GE Superdex Increase 75 5/150 GL
C31: GE Superdex Increase 75 10/300 GL
C32: GE Superdex Increase 200 5/150 GL
C33: GE Superdex Increase 200 10/300 GL
C34: None
C35: dSEC2
C36: Sepharose4B
C37: Superdex 200 Increase 3.2 300
C38: dSEC7
C39: Tosch
C40: dsec5
C41: Superose6_5_150
A42: Sample Type | C42: Sample
C43: Blank
C44: Cal. Std.
C45: Sys Suit
A47: Other valid name of columns
A50: Exp_Type | C50: X-ray_only
C51: X-ray_Regen
...

Sheet Agilent_Tray_format
A1: 96-well Format
A2: D1F-A01 | B2: D1F-B01 | C2: D1F-C01 | D2: D1F-D01 | E2: D1F-E01 | F2: D1F-F01 | G2: D1F-G01 | H2: D1F-H01
A3: D1F-A02 | B3: D1F-B02 | C3: D1F-C02 | D3: D1F-D02 | E3: D1F-E02 | F3: D1F-F02 | G3: D1F-G02 | H3: D1F-H02
A4: D1F-A03 | B4: D1F-B03 | C4: D1F-C03 | D4: D1F-D03 | E4: D1F-E03 | F4: D1F-F03 | G4: D1F-G03 | H4: D1F-H03
A5: D1F-A04 | B5: D1F-B04 | C5: D1F-C04 | D5: D1F-D04 | E5: D1F-E04 | F5: D1F-F04 | G5: D1F-G04 | H5: D1F-H04
A6: D1F-A05 | B6: D1F-B05 | C6: D1F-C05 | D6: D1F-D05 | E6: D1F-E05 | F6: D1F-F05 | G6: D1F-G05 | H6: D1F-H05
A7: D1F-A06 | B7: D1F-B06 | C7: D1F-C06 | D7: D1F-D06 | E7: D1F-E06 | F7: D1F-F06 | G7: D1F-G06 | H7: D1F-H06
A8: D1F-A07 | B8: D1F-B07 | C8: D1F-C07 | D8: D1F-D07 | E8: D1F-E07 | F8: D1F-F07 | G8: D1F-G07 | H8: D1F-H07
A9: D1F-A08 | B9: D1F-B08 | C9: D1F-C08 | D9: D1F-D08 | E9: D1F-E08 | F9: D1F-F08 | G9: D1F-G08 | H9: D1F-H08
A10: D1F-A09 | B10: D1F-B09 | C10: D1F-C09 | D10: D1F-D09 | E10: D1F-E09 | F10: D1F-F09 | G10: D1F-G09 | H10: D1F-H09
A11: D1F-A10 | B11: D1F-B10 | C11: D1F-C10 | D11: D1F-D10 | E11: D1F-E10 | F11: D1F-F10 | G11: D1F-G10 | H11: D1F-H10
A12: D1F-A11 | B12: D1F-B11 | C12: D1F-C11 | D12: D1F-D11 | E12: D1F-E11 | F12: D1F-F11 | G12: D1F-G11 | H12: D1F-H11
A13: D1F-A12 | B13: D1F-B12 | C13: D1F-C12 | D13: D1F-D12 | E13: D1F-E12 | F13: D1F-F12 | G13: D1F-G12 | H13: D1F-H12
A15: Vial Format
